Workbook

Sheet 000000

Sheet 100000

Sheet 200000

Sheet 300000

Sheet 400000

Sheet 25'06月
A1: ＵＦＪ銀行 | F1: SMBC上前津 | J1: =RIGHT(CELL("filename",A1),LEN(CELL("filename",A1))-FIND("]",CELL("filename",A1))) -> 25'06月
A3: 日付 | B3: 摘要 | C3: 入金 | D3: 出金 | E3: 残高 | F3: 摘要 | G3: 入金 | H3: 出金 | I3: 残高 | J3: 銀行残高計
C5: =SUM(C4:C4) -> 0 | D5: =SUM(D4:D4) -> 0 | E5: 2695329.5 | I5: 27338 | J5: 2722668
A6: 1 | B6: 名古屋信用保証貸付返済 | D6: 5892 | E6: =E5+C6-D6 -> 2689437.5 | I6: =I5+G6-H6 -> 27338 | J6: =SUM(E6,I6) -> 2716775.5
A7: 4 | B7: 名古屋市証書貸付返済 | D7: 7422 | E7: =E6+C7-D7 -> 2682015.5 | I7: =I6+G7-H7 -> 27338 | J7: =SUM(E7,I7) -> 2709353.5
A8: 10 | B8: 愛知県信用保証貸付返済 | D8: 11137 | E8: =E7+C8-D8 -> 2670878.5 | I8: =I7+G8-H8 -> 27338 | J8: =SUM(E8,I8) -> 2698216.5
B9: 名古屋市マル境対コロナ | D9: 13953 | E9: =E8+C9-D9 -> 2656925.5 | I9: =I8+G9-H9 -> 27338 | J9: =SUM(E9,I9) -> 2684263.5
B10: 金融公庫返済 | D10: 9753 | E10: =E9+C10-D10 -> 2647172.5 | I10: =I9+G10-H10 -> 27338 | J10: =SUM(E10,I10) -> 2674510.5
B11: ＮＴＴ | D11: 28722 | E11: =E10+C11-D11 -> 2618450.5 | I11: =I10+G11-H11 -> 27338 | J11: =SUM(E11,I11) -> 2645788.5
B12: TOM保守 | C12: 66000 | D12: 385 | E12: =E11+C12-D12 -> 2684065.5 | I12: =I11+G12-H12 -> 27338 | J12: =SUM(E12,I12) -> 2711403.5
B13: TF | D13: 29150 | E13: =E12+C13-D13 -> 2654915.5 | I13: =I12+G13-H13 -> 27338 | J13: =SUM(E13,I13) -> 2682253.5
A14: 20 | B14: 電脳：ジャパレン | C14: 9900000 | E14: =E13+C14-D14 -> 12554916 | I14: =I13+G14-H14 -> 27338 | J14: =SUM(E14,I14) -> 12582254
B15: DC | D15: 54358 | E15: =E14+C15-D15 -> 12500558 | I15: =I14+G15-H15 -> 27338 | J15: =SUM(E15,I15) -> 12527896
A16: 25 | B16: 東星-森下 | C16: 286000 | E16: =E15+C16-D16 -> 12786558 | I16: =I15+G16-H16 -> 27338 | J16: =SUM(E16,I16) -> 12813896
B17: 社保:延滞金 | D17: 800 | E17: =E16+C17-D17 -> 12785758 | I17: =I16+G17-H17 -> 27338 | J17: =SUM(E17,I17) -> 12813096
B18: BZ/振込手数料 | D18: 5060 | E18: =E17+C18-D18 -> 12780698 | I18: =I17+G18-H18 -> 27338 | J18: =SUM(E18,I18) -> 12808036
B19: BZ/振込手数料 | D19: 5104 | E19: =E18+C19-D19 -> 12775594 | I19: =I18+G19-H19 -> 27338 | J19: =SUM(E19,I19) -> 12802932
B20: KONICA-COPY:24 | D20: 1100 | E20: =E19+C20-D20 -> 12774494 | I20: =I19+G20-H20 -> 27338 | J20: =SUM(E20,I20) -> 12801832
B21: 特退共(退職金積立） | D21: 15000 | E21: =E20+C21-D21 -> 12759494 | I21: =I20+G21-H21 -> 27338 | J21: =SUM(E21,I21) -> 12786832
B22: 給与 | D22: 1159369 | E22: =E21+C22-D22 -> 11600124 | I22: =I21+G22-H22 -> 27338 | J22: =SUM(E22,I22) -> 11627462
A23: 31 | D23: 5000000 | E23: =E22+C23-D23 -> 6600124.5 | I23: =I22+G23-H23 -> 27338 | J23: =SUM(E23,I23) -> 6627462.5
B24: ASKUL | D24: 2090 | E24: =E23+C24-D24 -> 6598034.5 | I24: =I23+G24-H24 -> 27338 | J24: =SUM(E24,I24) -> 6625372.5
B25: AFRAC | D25: 4025 | E25: =E24+C25-D25 -> 6594009.5 | I25: =I24+G25-H25 -> 27338 | J25: =SUM(E25,I25) -> 6621347.5
B26: ORIX生命 | D26: 6095 | E26: =E25+C26-D26 -> 6587914.5 | I26: =I25+G26-H26 -> 27338 | J26: =SUM(E26,I26) -> 6615252.5
B27: RAKUTENクレカ:27 | D27: 177441 | E27: =E26+C27-D27 -> 6410473.5 | I27: =I26+G27-H27 -> 27338 | J27: =SUM(E27,I27) -> 6437811.5
B28: 住民税-一宮&刈谷 | D28: 18900 | E28: =E27+C28-D28 -> 6391573.5 | I28: =I27+G28-H28 -> 27338 | J28: =SUM(E28,I28) -> 6418911.5
B29: 労働保険 | D29: 5100 | E29: =E28+C29-D29 -> 6386473.5 | I29: =I28+G29-H29 -> 27338 | J29: =SUM(E29,I29) -> 6413811.5
B30: 消費税 | D30: 663700 | E30: =E29+C30-D30 -> 5722773.5 | I30: =I29+G30-H30 -> 27338 | J30: =SUM(E30,I30) -> 5750111.5
B31: 消費税 | D31: 19400 | E31: =E30+C31-D31 -> 5703373.5 | I31: =I30+G31-H31 -> 27338 | J31: =SUM(E31,I31) -> 5730711.5
B32: 名古屋信用保証貸付返済 | D32: 6524 | E32: =E31+C32-D32 -> 5696849.5 | I32: =I31+G32-H32 -> 27338 | J32: =SUM(E32,I32) -> 5724187.5
B33: 名古屋市証書貸付返済 | D33: 8217 | E33: =E32+C33-D33 -> 5688632.5 | I33: =I32+G33-H33 -> 27338 | J33: =SUM(E33,I33) -> 5715970.5
B34: 愛知県信用保証貸付返済 | D34: 12330 | E34: =E33+C34-D34 -> 5676302.5 | I34: =I33+G34-H34 -> 27338 | J34: =SUM(E34,I34) -> 5703640.5
B35: 名古屋市マル境対コロナ | D35: 15448 | E35: =E34+C35-D35 -> 5660854.5 | I35: =I34+G35-H35 -> 27338 | J35: =SUM(E35,I35) -> 5688192.5
... B39: ORIXリース | D39: 17160 | E39: =E38+C39-D39 -> 5604474.5 | I39: =I38+G39-H39 -> 27338 | J39: =SUM(E39,I39) -> 5631812.5
B40: TOM保守 | C40: 66000 | D40: 385 | E40: =E39+C40-D40 -> 5670089.5 | I40: =I39+G40-H40 -> 27338 | J40: =SUM(E40,I40) -> 5697427.5
E41: =E40+C41-D41 -> 5670089.5 | I41: =I40+G41-H41 -> 27338 | J41: =SUM(E41,I41) -> 5697427.5
E42: =E41+C42-D42 -> 5670089.5 | I42: =I41+G42-H42 -> 27338 | J42: =SUM(E42,I42) -> 5697427.5
E43: =E42+C43-D43 -> 5670089.5 | I43: =I42+G43-H43 -> 27338 | J43: =SUM(E43,I43) -> 5697427.5
E44: =E43+C44-D44 -> 5670089.5 | I44: =I43+G44-H44 -> 27338 | J44: =SUM(E44,I44) -> 5697427.5
B45: 家賃 | D45: 127600 | E45: =E44+C45-D45 -> 5542489.5 | I45: =I44+G45-H45 -> 27338 | J45: =SUM(E45,I45) -> 5569827.5
...

Sheet 25'07月
A1: ＵＦＪ銀行 | F1: SMBC上前津 | J1: =RIGHT(CELL("filename",A1),LEN(CELL("filename",A1))-FIND("]",CELL("filename",A1))) -> 25'07月
A3: 日付 | B3: 摘要 | C3: 入金 | D3: 出金 | E3: 残高 | F3: 摘要 | G3: 入金 | H3: 出金 | I3: 残高 | J3: 銀行残高計
C5: =SUM(C4:C4) -> 0 | D5: =SUM(D4:D4) -> 0 | E5: ='25''06月'!E52 -> 4269257.5 | G5: =SUM(G4:G4) -> 0 | H5: =SUM(H4:H4) -> 0 | I5: ='25''06月'!I52 -> 23331 | J5: ='25''06月'!J52 -> 4292588.5 | M5: 302311
A6: 1 | B6: TF | D6: 29150 | E6: =E5+C6-D6 -> 4240107.5 | I6: =I5+G6-H6 -> 23331 | J6: =SUM(E6,I6) -> 4263438.5 | M6: 281991
A7: 4 | B7: DC | D7: 31867 | E7: =E6+C7-D7 -> 4208240.5 | I7: =I6+G7-H7 -> 23331 | J7: =SUM(E7,I7) -> 4231571.5 | M7: 239405 | N7: =SUM(M5:M7) -> 823707
A8: 10 | B8: 三菱UFJニコスカード？ | D8: 22000 | E8: =E7+C8-D8 -> 4186240.5 | I8: =I7+G8-H8 -> 23331 | J8: =SUM(E8,I8) -> 4209571.5
B9: JCC空袋PC３台SBC&S | D9: 268170 | E9: =E8+C9-D9 -> 3918070.5 | I9: =I8+G9-H9 -> 23331 | J9: =SUM(E9,I9) -> 3941401.5 | L9: N | M9: 337317 | N9: =SUM(M5:M9) -> 1161024
D10: 26817 | E10: =E9+C10-D10 -> 3891253.5 | I10: =I9+G10-H10 -> 23331 | J10: =SUM(E10,I10) -> 3914584.5
B11: BZ/振込手数料 | D11: 5060 | E11: =E10+C11-D11 -> 3886193.5 | I11: =I10+G11-H11 -> 23331 | J11: =SUM(E11,I11) -> 3909524.5
D12: 4928 | E12: =E11+C12-D12 -> 3881265.5 | I12: =I11+G12-H12 -> 23331 | J12: =SUM(E12,I12) -> 3904596.5
B13: 特退共(退職金積立） | D13: 15000 | E13: =E12+C13-D13 -> 3866265.5 | I13: =I12+G13-H13 -> 23331 | J13: =SUM(E13,I13) -> 3889596.5
A14: 20 | B14: KONICA-COPY:24 | D14: 1100 | E14: =E13+C14-D14 -> 3865165.5 | I14: =I13+G14-H14 -> 23331 | J14: =SUM(E14,I14) -> 3888496.5
B15: 給与 | D15: 1161024 | E15: =E14+C15-D15 -> 2704141.5 | I15: =I14+G15-H15 -> 23331 | J15: =SUM(E15,I15) -> 2727472.5
A16: 25 | B16: AFRAC | D16: 4025 | E16: =E15+C16-D16 -> 2700116.5 | I16: =I15+G16-H16 -> 23331 | J16: =SUM(E16,I16) -> 2723447.5
B17: ORIX生命 | D17: 9170 | E17: =E16+C17-D17 -> 2690946.5 | I17: =I16+G17-H17 -> 23331 | J17: =SUM(E17,I17) -> 2714277.5
B18: RAKUTENクレカ:27 | D18: 309268 | E18: =E17+C18-D18 -> 2381678.5 | I18: =I17+G18-H18 -> 23331 | J18: =SUM(E18,I18) -> 2405009.5
B19: 社保 | D19: 333301 | E19: =E18+C19-D19 -> 2048377.5 | I19: =I18+G19-H19 -> 23331 | J19: =SUM(E19,I19) -> 2071708.5
E20: =E19+C20-D20 -> 2048377.5 | I20: =I19+G20-H20 -> 23331 | J20: =SUM(E20,I20) -> 2071708.5
B21: 名古屋信用保証貸付返済 | D21: 6734 | E21: =E20+C21-D21 -> 2041643.5 | I21: =I20+G21-H21 -> 23331 | J21: =SUM(E21,I21) -> 2064974.5
B22: 名古屋市証書貸付返済 | D22: 8482 | E22: =E21+C22-D22 -> 2033161.5 | I22: =I21+G22-H22 -> 23331 | J22: =SUM(E22,I22) -> 2056492.5
A23: 31 | B23: 愛知県信用保証貸付返済 | D23: 12728 | E23: =E22+C23-D23 -> 2020433.5 | I23: =I22+G23-H23 -> 23331 | J23: =SUM(E23,I23) -> 2043764.5
B24: 名古屋市マル境対コロナ | D24: 15946 | E24: =E23+C24-D24 -> 2004487.5 | I24: =I23+G24-H24 -> 23331 | J24: =SUM(E24,I24) -> 2027818.5
B25: 金融公庫返済 | D25: 9753 | E25: =E24+C25-D25 -> 1994734.5 | I25: =I24+G25-H25 -> 23331 | J25: =SUM(E25,I25) -> 2018065.5
B26: ＮＴＴ | D26: 19653 | E26: =E25+C26-D26 -> 1975081.5 | I26: =I25+G26-H26 -> 23331 | J26: =SUM(E26,I26) -> 1998412.5
B27: NTT光ネクスト | D27: 10780 | E27: =E26+C27-D27 -> 1964301.5 | I27: =I26+G27-H27 -> 23331 | J27: =SUM(E27,I27) -> 1987632.5
E28: =E27+C28-D28 -> 1964301.5 | I28: =I27+G28-H28 -> 23331 | J28: =SUM(E28,I28) -> 1987632.5
E29: =E28+C29-D29 -> 1964301.5 | I29: =I28+G29-H29 -> 23331 | J29: =SUM(E29,I29) -> 1987632.5
B30: Hikari-SYS | C30: 165000 | E30: =E29+C30-D30 -> 2129301.5 | I30: =I29+G30-H30 -> 23331 | J30: =SUM(E30,I30) -> 2152632.5
E31: =E30+C31-D31 -> 2129301.5 | I31: =I30+G31-H31 -> 23331 | J31: =SUM(E31,I31) -> 2152632.5
B32: TOM保守 | C32: 66000 | D32: 385 | E32: =E31+C32-D32 -> 2194916.5 | I32: =I31+G32-H32 -> 23331 | J32: =SUM(E32,I32) -> 2218247.5
E33: =E32+C33-D33 -> 2194916.5 | I33: =I32+G33-H33 -> 23331 | J33: =SUM(E33,I33) -> 2218247.5
E34: =E33+C34-D34 -> 2194916.5 | I34: =I33+G34-H34 -> 23331 | J34: =SUM(E34,I34) -> 2218247.5
E35: =E34+C35-D35 -> 2194916.5 | I35: =I34+G35-H35 -> 23331 | J35: =SUM(E35,I35) -> 2218247.5
E36: =E35+C36-D36 -> 2194916.5 | I36: =I35+G36-H36 -> 23331 | J36: =SUM(E36,I36) -> 2218247.5
E37: =E36+C37-D37 -> 2194916.5 | I37: =I36+G37-H37 -> 23331 | J37: =SUM(E37,I37) -> 2218247.5
E38: =E37+C38-D38 -> 2194916.5 | I38: =I37+G38-H38 -> 23331 | J38: =SUM(E38,I38) -> 2218247.5
E39: =E38+C39-D39 -> 2194916.5 | I39: =I38+G39-H39 -> 23331 | J39: =SUM(E39,I39) -> 2218247.5
E40: =E39+C40-D40 -> 2194916.5 | I40: =I39+G40-H40 -> 23331 | J40: =SUM(E40,I40) -> 2218247.5
E41: =E40+C41-D41 -> 2194916.5 | I41: =I40+G41-H41 -> 23331 | J41: =SUM(E41,I41) -> 2218247.5
B42: ORIXリース | D42: 21560 | E42: =E41+C42-D42 -> 2173356.5 | I42: =I41+G42-H42 -> 23331 | J42: =SUM(E42,I42) -> 2196687.5
...

Sheet 25'08月
A1: ＵＦＪ銀行 | F1: SMBC上前津 | J1: =RIGHT(CELL("filename",A1),LEN(CELL("filename",A1))-FIND("]",CELL("filename",A1))) -> 25'08月
A3: 日付 | B3: 摘要 | C3: 入金 | D3: 出金 | E3: 残高 | F3: 摘要 | G3: 入金 | H3: 出金 | I3: 残高 | J3: 銀行残高計
C5: =SUM(C4:C4) -> 0 | D5: =SUM(D4:D4) -> 0 | E5: ='25''07月'!E52 -> 2003464.5 | G5: =SUM(G4:G4) -> 0 | H5: =SUM(H4:H4) -> 0 | I5: ='25''07月'!I52 -> 19195 | J5: ='25''07月'!J52 -> 2022659.5
A6: 1 | B6: TF | D6: 29150 | E6: =E5+C6-D6 -> 1974314.5 | I6: =I5+G6-H6 -> 19195 | J6: =SUM(E6,I6) -> 1993509.5
A7: 4 | B7: HMJ- | C7: 96000 | E7: =E6+C7-D7 -> 2070314.5 | I7: =I6+G7-H7 -> 19195 | J7: =SUM(E7,I7) -> 2089509.5
A8: 10 | B8: SKｼｽﾃﾑ:KeikoG-202506 | D8: 27225 | E8: =E7+C8-D8 -> 2043089.5 | I8: =I7+G8-H8 -> 19195 | J8: =SUM(E8,I8) -> 2062284.5
B9: SKｼｽﾃﾑ:KeikoG-202507 | D9: 27225 | E9: =E8+C9-D9 -> 2015864.5 | I9: =I8+G9-H9 -> 19195 | J9: =SUM(E9,I9) -> 2035059.5
B10: DC | D10: 36259 | E10: =E9+C10-D10 -> 1979605.5 | I10: =I9+G10-H10 -> 19195 | J10: =SUM(E10,I10) -> 1998800.5
B11: 小口現金 | D11: 50000 | E11: =E10+C11-D11 -> 1929605.5 | I11: =I10+G11-H11 -> 19195 | J11: =SUM(E11,I11) -> 1948800.5
B12: ATM手数料 | D12: 220 | E12: =E11+C12-D12 -> 1929385.5 | I12: =I11+G12-H12 -> 19195 | J12: =SUM(E12,I12) -> 1948580.5
B13: 利息 | C13: 2182 | E13: =E12+C13-D13 -> 1931567.5 | I13: =I12+G13-H13 -> 19195 | J13: =SUM(E13,I13) -> 1950762.5
A14: 20 | B14: BZ/振込手数料 | D14: 5060 | E14: =E13+C14-D14 -> 1926507.5 | I14: =I13+G14-H14 -> 19195 | J14: =SUM(E14,I14) -> 1945702.5
B15: BZ/振込手数料 | D15: 3564 | E15: =E14+C15-D15 -> 1922943.5 | I15: =I14+G15-H15 -> 19195 | J15: =SUM(E15,I15) -> 1942138.5
A16: 25 | B16: 特退共(退職金積立） | D16: 15000 | E16: =E15+C16-D16 -> 1907943.5 | I16: =I15+G16-H16 -> 19195 | J16: =SUM(E16,I16) -> 1927138.5
B17: KONICA-COPY:24 | D17: 2233 | E17: =E16+C17-D17 -> 1905710.5 | I17: =I16+G17-H17 -> 19195 | J17: =SUM(E17,I17) -> 1924905.5
B18: 給与 | D18: 1161024 | E18: =E17+C18-D18 -> 744686.5 | I18: =I17+G18-H18 -> 19195 | J18: =SUM(E18,I18) -> 763881.5
B19: 社保 | D19: 333301 | E19: =E18+C19-D19 -> 411385.5 | I19: =I18+G19-H19 -> 19195 | J19: =SUM(E19,I19) -> 430580.5
B20: AFRAC | D20: 4025 | E20: =E19+C20-D20 -> 407360.5 | I20: =I19+G20-H20 -> 19195 | J20: =SUM(E20,I20) -> 426555.5
B21: ORIX生命 | D21: 9170 | E21: =E20+C21-D21 -> 398190.5 | I21: =I20+G21-H21 -> 19195 | J21: =SUM(E21,I21) -> 417385.5
B22: RAKUTENクレカ:27 | D22: 225947 | E22: =E21+C22-D22 -> 172243.5 | I22: =I21+G22-H22 -> 19195 | J22: =SUM(E22,I22) -> 191438.5
A23: 31 | E23: =E22+C23-D23 -> 172243.5 | I23: =I22+G23-H23 -> 19195 | J23: =SUM(E23,I23) -> 191438.5
B24: 家賃 | D24: 127600 | E24: =E23+C24-D24 -> 44643.5 | I24: =I23+G24-H24 -> 19195 | J24: =SUM(E24,I24) -> 63838.5
B25: 会計士 | D25: 32931 | E25: =E24+C25-D25 -> 11712.5 | I25: =I24+G25-H25 -> 19195 | J25: =SUM(E25,I25) -> 30907.5
B26: 駐車場 | D26: 5000 | E26: =E25+C26-D26 -> 6712.5 | I26: =I25+G26-H26 -> 19195 | J26: =SUM(E26,I26) -> 25907.5
B27: 伊勢昆布-弥生連携 | C27: 165000 | E27: =E26+C27-D27 -> 171712.5 | I27: =I26+G27-H27 -> 19195 | J27: =SUM(E27,I27) -> 190907.5
B28: HMJ-給与・賞与保守 | C28: 990000 | E28: =E27+C28-D28 -> 1161712.5 | I28: =I27+G28-H28 -> 19195 | J28: =SUM(E28,I28) -> 1180907.5
B29: JCC-検査データMVR対応 | C29: 297000 | D29: 3626 | E29: =E28+C29-D29 -> 1455086.5 | I29: =I28+G29-H29 -> 19195 | J29: =SUM(E29,I29) -> 1474281.5
E30: =E29+C30-D30 -> 1455086.5 | I30: =I29+G30-H30 -> 19195 | J30: =SUM(E30,I30) -> 1474281.5
E31: =E30+C31-D31 -> 1455086.5 | I31: =I30+G31-H31 -> 19195 | J31: =SUM(E31,I31) -> 1474281.5
B32: TOM保守 | C32: 66000 | D32: 385 | E32: =E31+C32-D32 -> 1520701.5 | I32: =I31+G32-H32 -> 19195 | J32: =SUM(E32,I32) -> 1539896.5
E33: =E32+C33-D33 -> 1520701.5 | I33: =I32+G33-H33 -> 19195 | J33: =SUM(E33,I33) -> 1539896.5
B34: 名古屋信用保証貸付返済 | D34: 6103 | E34: =E33+C34-D34 -> 1514598.5 | I34: =I33+G34-H34 -> 19195 | J34: =SUM(E34,I34) -> 1533793.5
B35: 名古屋市証書貸付返済 | D35: 7687 | E35: =E34+C35-D35 -> 1506911.5 | I35: =I34+G35-H35 -> 19195 | J35: =SUM(E35,I35) -> 1526106.5
B36: 愛知県信用保証貸付返済 | D36: 11534 | E36: =E35+C36-D36 -> 1495377.5 | I36: =I35+G36-H36 -> 19195 | J36: =SUM(E36,I36) -> 1514572.5
B37: 名古屋市マル境対コロナ | D37: 14451 | E37: =E36+C37-D37 -> 1480926.5 | I37: =I36+G37-H37 -> 19195 | J37: =SUM(E37,I37) -> 1500121.5
B38: 金融公庫返済 | D38: 9753 | E38: =E37+C38-D38 -> 1471173.5 | I38: =I37+G38-H38 -> 19195 | J38: =SUM(E38,I38) -> 1490368.5
E39: =E38+C39-D39 -> 1471173.5 | I39: =I38+G39-H39 -> 19195 | J39: =SUM(E39,I39) -> 1490368.5
B40: ＮＴＴ | D40: 18783 | E40: =E39+C40-D40 -> 1452390.5 | I40: =I39+G40-H40 -> 19195 | J40: =SUM(E40,I40) -> 1471585.5
B41: NTT光ネクスト | D41: 10780 | E41: =E40+C41-D41 -> 1441610.5 | I41: =I40+G41-H41 -> 19195 | J41: =SUM(E41,I41) -> 1460805.5
B42: ORIXリース | D42: 29851 | E42: =E41+C42-D42 -> 1411759.5 | I42: =I41+G42-H42 -> 19195 | J42: =SUM(E42,I42) -> 1430954.5
...
