Workbook

Sheet クレジット
A1: ㈱ | B1: 【クレジット】 | C1: トヨタF | E1: R8.09.11 引落し分
A2: 日付 | B2: 勘定科目 | C2: 消費税区分 | D2: 支払金額 | E2: 摘要（相手先・内容） | F2: 備考 | I2: 入力方法 | M2: コピぺ
I3: 〇〇/〇〇 | J3: プルダウン・コピぺ | K3: プルダウン・コピぺ
I4: 日付 | J4: 勘定科目 | K4: 消費税区分
I5: 11/4 | J5: 福利厚生費 | K5: 仕入10％
I6: 11/5 | J6: 消耗品費 | K6: 仕入8％（軽）
I7: 11/6 | J7: 交際費 | K7: 対象外
I8: 11/7 | J8: 旅費交通費 | K8: 仕入8％（旧）
I9: 11/8 | J9: 車輌燃料費
J10: 租税公課
J11: 広告宣伝費 | K11: 仕入10％
J12: 荷造運賃 | K12: 仕入8％（軽）
J13: 通信費 | K13: 対象外
J14: 水道光熱費 | K14: 仕入8％（旧）
J15: 修繕費
J16: 賃借料
J17: 雑費 | K17: 仕入10％
J18: 仮払金 | K18: 仕入8％（軽）
K19: 対象外
J20: 保険料 | K20: 仕入8％（旧）
J21: 支払手数料
J22: リース料
J23: 会議費 | K23: 仕入10％
J24: 諸会費 | K24: 仕入8％（軽）
J25: 雑収入 | K25: 対象外
J26: 仕入高 | K26: 仕入8％（旧）
J27: 外注費
I32: 摘要に記載する隠語（記号）の例示
I33: (1)インボイス番号ない場合 ①
I34: ※上場企業、ETCなどは①不要
I35: (2)軽減税率の場合 ⑧
I36: (3)軽減税率でインボイス番号がない場合 ⑧①
I37: (4)対象外(不課税)・非課税の場合 ②
I38: ※税金、保険料などは②不要
I41: 例示
I42: 日付 | J42: 勘定科目 | K42: 消費税区分 | L42: 支払金額 | M42: 相手先・内容
I43: 46236 | J43: 交際費 | K43: 仕入10％ | L43: 10000 | M43: 藤原ゴルフ
I44: 46236 | J44: 交際費 | K44: 対象外 | L44: 850 | M44: 藤原ゴルフ 利用税等 ②
I45: 46236 | J45: 交際費 | K45: 仕入8％(軽) | L45: 216 | M45: 藤原ゴルフ ドリンク代 ⑧
I46: 46239 | J46: 車輌燃料費 | K46: 仕入10％ | L46: 2282 | M46: エネオス 軽油代
...

Sheet CSV
A1: =クレジット!A1 -> ㈱ | B1: =クレジット!B1 -> 【クレジット】 | C1: =クレジット!C1 -> トヨタF | D1: =クレジット!E1 -> R8.09.11 引落し分
D2: 日付 | E2: 勘定科目 | H2: 消費税区分 | I2: 金額 | K2: 勘定科目 | N2: 消費税区分 | O2: 金額 | Q2: 摘要
A3: 2000 | D3: =クレジット!A3 -> 0 | E3: =クレジット!B3 -> 0 | H3: =クレジット!C3 -> 0 | I3: =クレジット!D3 -> 0 | K3: クレジット複合 | N3: 対象外 | O3: =I3 -> 0 | Q3: =クレジット!E3 -> 0 | T3: 0 | Y3: no
A4: 2000 | D4: =クレジット!A4 -> 0 | E4: =クレジット!B4 -> 0 | H4: =クレジット!C4 -> 0 | I4: =クレジット!D4 -> 0 | K4: クレジット複合 | N4: 対象外 | O4: =I4 -> 0 | Q4: =クレジット!E4 -> 0 | T4: 0 | Y4: no
A5: 2000 | D5: =クレジット!A5 -> 0 | E5: =クレジット!B5 -> 0 | H5: =クレジット!C5 -> 0 | I5: =クレジット!D5 -> 0 | K5: クレジット複合 | N5: 対象外 | O5: =I5 -> 0 | Q5: =クレジット!E5 -> 0 | T5: 0 | Y5: no
A6: 2000 | D6: =クレジット!A6 -> 0 | E6: =クレジット!B6 -> 0 | H6: =クレジット!C6 -> 0 | I6: =クレジット!D6 -> 0 | K6: クレジット複合 | N6: 対象外 | O6: =I6 -> 0 | Q6: =クレジット!E6 -> 0 | T6: 0 | Y6: no
A7: 2000 | D7: =クレジット!A7 -> 0 | E7: =クレジット!B7 -> 0 | H7: =クレジット!C7 -> 0 | I7: =クレジット!D7 -> 0 | K7: クレジット複合 | N7: 対象外 | O7: =I7 -> 0 | Q7: =クレジット!E7 -> 0 | T7: 0 | Y7: no
A8: 2000 | D8: =クレジット!A8 -> 0 | E8: =クレジット!B8 -> 0 | H8: =クレジット!C8 -> 0 | I8: =クレジット!D8 -> 0 | K8: クレジット複合 | N8: 対象外 | O8: =I8 -> 0 | Q8: =クレジット!E8 -> 0 | T8: 0 | Y8: no
A9: 2000 | D9: =クレジット!A9 -> 0 | E9: =クレジット!B9 -> 0 | H9: =クレジット!C9 -> 0 | I9: =クレジット!D9 -> 0 | K9: クレジット複合 | N9: 対象外 | O9: =I9 -> 0 | Q9: =クレジット!E9 -> 0 | T9: 0 | Y9: no
A10: 2000 | D10: =クレジット!A10 -> 0 | E10: =クレジット!B10 -> 0 | H10: =クレジット!C10 -> 0 | I10: =クレジット!D10 -> 0 | K10: クレジット複合 | N10: 対象外 | O10: =I10 -> 0 | Q10: =クレジット!E10 -> 0 | T10: 0 | Y10: no
A11: 2000 | D11: =クレジット!A11 -> 0 | E11: =クレジット!B11 -> 0 | H11: =クレジット!C11 -> 0 | I11: =クレジット!D11 -> 0 | K11: クレジット複合 | N11: 対象外 | O11: =I11 -> 0 | Q11: =クレジット!E11 -> 0 | T11: 0 | Y11: no
A12: 2000 | D12: =クレジット!A12 -> 0 | E12: =クレジット!B12 -> 0 | H12: =クレジット!C12 -> 0 | I12: =クレジット!D12 -> 0 | K12: クレジット複合 | N12: 対象外 | O12: =I12 -> 0 | Q12: =クレジット!E12 -> 0 | T12: 0 | Y12: no
A13: 2000 | D13: =クレジット!A13 -> 0 | E13: =クレジット!B13 -> 0 | H13: =クレジット!C13 -> 0 | I13: =クレジット!D13 -> 0 | K13: クレジット複合 | N13: 対象外 | O13: =I13 -> 0 | Q13: =クレジット!E13 -> 0 | T13: 0 | Y13: no
A14: 2000 | D14: =クレジット!A14 -> 0 | E14: =クレジット!B14 -> 0 | H14: =クレジット!C14 -> 0 | I14: =クレジット!D14 -> 0 | K14: クレジット複合 | N14: 対象外 | O14: =I14 -> 0 | Q14: =クレジット!E14 -> 0 | T14: 0 | Y14: no
... A56: 2000 | D56: =クレジット!A56 -> 0 | E56: =クレジット!B56 -> 0 | H56: =クレジット!C56 -> 0 | I56: =クレジット!D56 -> 0 | K56: クレジット複合 | N56: 対象外 | O56: =I56 -> 0 | Q56: =クレジット!E56 -> 0 | T56: 0 | Y56: no
A57: 計 | I57: =SUM(I3:I56) -> 0 | O57: =SUM(O3:O56) -> 0

Sheet Sheet1
