Workbook

Sheet 現金帳
A1: 現金出納帳帳 | C1: R8.09月 | K1: 入力方法
A2: 日付 | B2: 勘定科目 | C2: 摘要（支払先/支払内容） | E2: 消費税区分 | F2: 収入金額 | G2: 支出金額 | H2: 現金残高 | K2: 〇〇/〇〇 | M2: コピぺ | O2: コピぺ
K3: 日付 | M3: 勘定科目 | O3: 消費税区分
C4: 前月繰越金額 | H4: 0 | K4: 11/4 | M4: 仕入高 | O4: 仕入10％
H5: =H4+F5-G5 -> 0 | K5: 11/5 | M5: 外注費 | O5: 仕入8％(軽)
H6: =H5+F6-G6 -> 0 | K6: 11/6 | M6: 福利厚生費 | O6: 不課税
H7: =H6+F7-G7 -> 0 | K7: 11/7 | M7: 広告宣伝費 | O7: 非課税
H8: =H7+F8-G8 -> 0 | K8: 11/8 | M8: 荷造運賃 | O8: 仕入8％(軽)
H9: =H8+F9-G9 -> 0 | M9: 旅費交通費
H10: =H9+F10-G10 -> 0 | M10: 通信費 | O10: 仕入10％
H11: =H10+F11-G11 -> 0 | M11: 水道光熱費 | O11: 仕入8％(軽)
H12: =H11+F12-G12 -> 0 | M12: 租税公課 | O12: 不課税
H13: =H12+F13-G13 -> 0 | M13: 交際費 | O13: 非課税
H14: =H13+F14-G14 -> 0 | M14: 消耗品費 | O14: 仕入8％(軽)
H15: =H14+F15-G15 -> 0 | M15: 事務用品費
H16: =H15+F16-G16 -> 0 | M16: 賃借料 | O16: 仕入10％
H17: =H16+F17-G17 -> 0 | M17: 修繕費 | O17: 仕入8％(軽)
H18: =H17+F18-G18 -> 0 | M18: 保険料 | O18: 不課税
H19: =H18+F19-G19 -> 0 | M19: 支払手数料 | O19: 非課税
H20: =H19+F20-G20 -> 0 | M20: リース料 | O20: 仕入8％(軽)
H21: =H20+F21-G21 -> 0 | M21: 会議費
H22: =H21+F22-G22 -> 0 | M22: 車輌燃料費 | O22: 仕入10％
H23: =H22+F23-G23 -> 0 | M23: 諸会費 | O23: 仕入8％(軽)
H24: =H23+F24-G24 -> 0 | M24: 雑費 | O24: 不課税
H25: =H24+F25-G25 -> 0 | M25: 雑収入 | O25: 非課税
H26: =H25+F26-G26 -> 0 | M26: 仮払金 | O26: 仕入8％(軽)
H27: =H26+F27-G27 -> 0
H28: =H27+F28-G28 -> 0 | K28: 摘要に記載する隠号（記号）の例示
H29: =H28+F29-G29 -> 0 | K29: (1)インボイス番号ない場合 ①
H30: =H29+F30-G30 -> 0 | K30: (2)軽減税率の場合 ⑧
H31: =H30+F31-G31 -> 0 | K31: (3)軽減税率でインボイス番号がない場合 ⑧①
H32: =H31+F32-G32 -> 0 | K32: (4)不課税・非課税の場合 ②
H33: =H32+F33-G33 -> 0
H34: =H33+F34-G34 -> 0 | K34: 例示
H35: =H34+F35-G35 -> 0 | K35: 日付 | M35: 勘定科目 | O35: 摘要 | Q35: 消費税区分 | R35: 収入金額 | S35: 支出金額
H36: =H35+F36-G36 -> 0 | K36: 46236 | M36: 交際費 | O36: 藤原ゴルフ | Q36: 仕入10％ | S36: 10000
H37: =H36+F37-G37 -> 0 | K37: 46236 | M37: 交際費 | O37: 藤原ゴルフ 利用税 ② | Q37: 不課税 | S37: 850
H38: =H37+F38-G38 -> 0 | K38: 46236 | M38: 交際費 | O38: 藤原ゴルフ ドリンク代 ⑧ | Q38: 仕入8％(軽) | S38: 216
H39: =H38+F39-G39 -> 0 | K39: 46239 | M39: 燃料費 | O39: エネオス 軽油代 | Q39: 仕入10％ | S39: 2282
H40: =H39+F40-G40 -> 0 | K40: 46239 | M40: 燃料費 | O40: エネオス 軽油税 ② | Q40: 不課税 | S40: 6250
...

Sheet CSV
A1: =現金帳!A1 -> 現金出納帳帳 | C1: =現金帳!C1 -> R8.09月
D3: 日付 | E3: 勘定科目 | H3: 消費税区分 | I3: 金額 | K3: 勘定科目 | N3: 消費税区分 | O3: 金額 | Q3: 摘要
A5: 2000 | D5: =現金帳!A5 -> 0 | E5: =現金帳!B5 -> 0 | H5: =現金帳!E5 -> 0 | I5: =現金帳!G5 -> 0 | K5: 現金 | N5: 対象外 | O5: =I5 -> 0 | Q5: =現金帳!C5 -> 0 | T5: 0 | Y5: no
A6: 2000 | D6: =現金帳!A6 -> 0 | E6: =現金帳!B6 -> 0 | H6: =現金帳!E6 -> 0 | I6: =現金帳!G6 -> 0 | K6: 現金 | N6: 対象外 | O6: =I6 -> 0 | Q6: =現金帳!C6 -> 0 | T6: 0 | Y6: no
A7: 2000 | D7: =現金帳!A7 -> 0 | E7: =現金帳!B7 -> 0 | H7: =現金帳!E7 -> 0 | I7: =現金帳!G7 -> 0 | K7: 現金 | N7: 対象外 | O7: =I7 -> 0 | Q7: =現金帳!C7 -> 0 | T7: 0 | Y7: no
A8: 2000 | D8: =現金帳!A8 -> 0 | E8: =現金帳!B8 -> 0 | H8: =現金帳!E8 -> 0 | I8: =現金帳!G8 -> 0 | K8: 現金 | N8: 対象外 | O8: =I8 -> 0 | Q8: =現金帳!C8 -> 0 | T8: 0 | Y8: no
A9: 2000 | D9: =現金帳!A9 -> 0 | E9: =現金帳!B9 -> 0 | H9: =現金帳!E9 -> 0 | I9: =現金帳!G9 -> 0 | K9: 現金 | N9: 対象外 | O9: =I9 -> 0 | Q9: =現金帳!C9 -> 0 | T9: 0 | Y9: no
A10: 2000 | D10: =現金帳!A10 -> 0 | E10: =現金帳!B10 -> 0 | H10: =現金帳!E10 -> 0 | I10: =現金帳!G10 -> 0 | K10: 現金 | N10: 対象外 | O10: =I10 -> 0 | Q10: =現金帳!C10 -> 0 | T10: 0 | Y10: no
A11: 2000 | D11: =現金帳!A11 -> 0 | E11: =現金帳!B11 -> 0 | H11: =現金帳!E11 -> 0 | I11: =現金帳!G11 -> 0 | K11: 現金 | N11: 対象外 | O11: =I11 -> 0 | Q11: =現金帳!C11 -> 0 | T11: 0 | Y11: no
A12: 2000 | D12: =現金帳!A12 -> 0 | E12: =現金帳!B12 -> 0 | H12: =現金帳!E12 -> 0 | I12: =現金帳!G12 -> 0 | K12: 現金 | N12: 対象外 | O12: =I12 -> 0 | Q12: =現金帳!C12 -> 0 | T12: 0 | Y12: no
A13: 2000 | D13: =現金帳!A13 -> 0 | E13: =現金帳!B13 -> 0 | H13: =現金帳!E13 -> 0 | I13: =現金帳!G13 -> 0 | K13: 現金 | N13: 対象外 | O13: =I13 -> 0 | Q13: =現金帳!C13 -> 0 | T13: 0 | Y13: no
A14: 2000 | D14: =現金帳!A14 -> 0 | E14: =現金帳!B14 -> 0 | H14: =現金帳!E14 -> 0 | I14: =現金帳!G14 -> 0 | K14: 現金 | N14: 対象外 | O14: =I14 -> 0 | Q14: =現金帳!C14 -> 0 | T14: 0 | Y14: no
A15: 2000 | D15: =現金帳!A15 -> 0 | E15: =現金帳!B15 -> 0 | H15: =現金帳!E15 -> 0 | I15: =現金帳!G15 -> 0 | K15: 現金 | N15: 対象外 | O15: =I15 -> 0 | Q15: =現金帳!C15 -> 0 | T15: 0 | Y15: no
A16: 2000 | D16: =現金帳!A16 -> 0 | E16: =現金帳!B16 -> 0 | H16: =現金帳!E16 -> 0 | I16: =現金帳!G16 -> 0 | K16: 現金 | N16: 対象外 | O16: =I16 -> 0 | Q16: =現金帳!C16 -> 0 | T16: 0 | Y16: no
... A44: 2000 | D44: =現金帳!A44 -> 0 | E44: =現金帳!B44 -> 0 | H44: =現金帳!E44 -> 0 | I44: =現金帳!G44 -> 0 | K44: 現金 | N44: 対象外 | O44: =I44 -> 0 | Q44: =現金帳!C44 -> 0 | T44: 0 | Y44: no
A45: 計 | I45: =SUM(I5:I44) -> 0 | O45: =SUM(O5:O44) -> 0

Sheet Sheet1
